<?xml version="1.0"?>
<sdf version="1.7">
  <model name="mobile_base">
    <link name="mobile_base_link_0">
      <inertial>
        <mass>100</mass>
        <inertia>
          <ixx>0.0041666666666666675</ixx>
          <ixy>0.0</ixy>
          <ixz>0.0</ixz>
          <iyy>0.0041666666666666675 </iyy>
          <iyz>0.0</iyz>
          <izz>0.001666666666666667</izz>
        </inertia>
      </inertial>
      <gravity>1</gravity>
    </link>
    <joint name="mobile_base_joint_x" type="prismatic">
      <child>mobile_base_link_0</child>
      <parent>world</parent>
      <axis>
        <xyz expressed_in="__model__">1 0 0</xyz>
        <limit>
          <lower>-1</lower>
          <upper>1</upper>
          <effort>80</effort>
          <stiffness>15000</stiffness>
          <velocity>1</velocity>
        </limit>
        <dynamics>
          <damping>0.0</damping>
          <friction>0</friction>
          <spring_reference>0</spring_reference>
          <spring_stiffness>0</spring_stiffness>
        </dynamics>
      </axis>
      <pose>0 0 0 0 0 0</pose>
    </joint>
    <link name="mobile_base_link_1">
      <inertial>
        <mass>100</mass>
        <inertia>
          <ixx>0.0041666666666666675</ixx>
          <ixy>0.0</ixy>
          <ixz>0.0</ixz>
          <iyy>0.0041666666666666675 </iyy>
          <iyz>0.0</iyz>
          <izz>0.001666666666666667</izz>
        </inertia>
      </inertial>
      <gravity>1</gravity>
    </link>
    <joint name="mobile_base_joint_y" type="prismatic">
      <child>mobile_base_link_1</child>
      <parent>mobile_base_link_0</parent>
      <axis>
        <xyz expressed_in="__model__">0 1 0</xyz>
        <limit>
          <lower>-1</lower>
          <upper>1</upper>
          <effort>80</effort>
          <stiffness>15000</stiffness>
          <velocity>1</velocity>
        </limit>
        <dynamics>
          <damping>0.0</damping>
          <friction>0</friction>
          <spring_reference>0</spring_reference>
          <spring_stiffness>0</spring_stiffness>
        </dynamics>
      </axis>
      <pose>0 0 0 0 0 0</pose>
    </joint>
    <static>0</static>
    <plugin name="gazebo_ros_controller" filename="libgazebo_ros_control.so">
      <robotNamespace>/mobile_base</robotNamespace>
    </plugin>
  </model>
</sdf>